# 📢 예외처리 

### 프로그램 오류 
프로그램이 실행 중 어떤 원인에 의해 오작동하거나 비정상적으로 죵료되는 원인을 오류 또는 에러라고 한다.
* 발생시점에 따라 , `컴파일 에러`와 `런타임 에러`로 나눌 수 있다ㅣ.
* `컴파일 에러` :  컴파일 시에 발생하는 에러 
* `런타임 에러` : 실행 시에 발생하는 에러
* `논리적 에러` : 실행은 되지만, 의도와 다르게 동작하는 것

컴파일러가 소스코드의 기본적인 사항은 컴파일 시에 걸러줄 수 있지만, 실행 중에 발생하는 잠재적인 오류까지 검사할 수는 없기 때문에 컴파일은 잘 되었어도 실행 중에 에러에 의해서 잘못된 결과를 얻거나 비정상적으로 종료될 수 있다.<br>
**자바에서는 실행 시 발생할 수 있는 오류를 `에러(error)`와 `예외(exception)` 두 가지로 구분한다.**
* `에러` : 프로그램 코드에 의해서 수습될 수 없는 심각한 오류 - ex) 메모리 부족(OutOfMemoryError) , 스택오버플로우(StackOveflowError) 
* `예외` : 프로그램 코드에 의해서 수습될 수 있는 다소 미약한 오류

예외는 발생하더라도 프로그래머가 이에 대한 적절한 코드를 미리 작성해 놓음으로써 비정상적인 종료를 막을 수 있다.

## 예외 클래스의 계층구조
<img src="https://github.com/dev-kmj/java-study/assets/74237301/dc3b96df-2498-44ff-9ae1-b42cb63e0ef9" width=490 height=310>

* 모든 예외의 부모인 최상위 클래스는 Exception클래스이다. 
* `RuntimeException`클래스들은 주로 프로그래머의 실수에 의해서 발생될 수 있는 예외들로 주로 자바의 프로그래밍 요소들과 관계있다.
    * 형변환을 잘못한 경우 - ClassCastException
    * 정수를 0으로 나누려고 하는 경우 - ArithmeticException

## 예외 처리하기 : try-catch문 

```java
class Exception {
  public static void main(String args[]) {
    int number = 100;
    int result = 0;

    for(int i = 0; i < 10; i++) {
      try {
        result = number / (int)(Math.random() * 10);
        System.out.println(result);
      } catch (ArithmeticException e) {
        System.out.println("0");
    }
}
```
실수를 0으로 나누는 경우는 예외가 발생하지 않지만, 실수를 0으로 나누는 것은 금지되어 있기 때문에 `ArithmaticException`예외가 발생한다. <br>
* 예외처리구문을 추가하면 예외 발생 시 해당하는 catch블럭을 찾아 그 안의 문장들을 실행 한 뒤 try-catch문을 벗어나 for문의 반복 수행하여 작업을 모두 맞치고 정상적으로 종료된다. 
* 만일 예외처리를 하지 않았다면, 예외 발생 시 프로그램이 비정상적으로 종료되었을 것이다.
  
**try블럭 내에서 예외가 발생한 경우**
1) 발생한 예외와 일치하는 catch블럭이 있는지 확인한다.
2) 일치하는 catch블럭을 찾는다면, 그 안의 문장들을 수행하고 전체 try-catch문을 빠져나가서 다음 문장을 계쏙해서 수행한다. 일치하는 catch블럭을 찾지 못하면, 예외는 처리되지 못한다.
   
**try블럭 내에서 예외가 발생하지 않은 경우**<br>
catch블럭을 거치지 않고 전체 try-catch문을 빠져나가서 수행을 계속한다. 

예외가 발생했을 때 생성되는 예외 클래스의 인스턴스에는 발생한 예외에 대한 정보가 담겨있다. 
* `printStackTrace()`: 예외발생 당시의 호출스택(Call Stack)에 있었던 메서드의 정보와 예외 메시지를 화면에 출력한다.
* `getMessage()`: 발생한 예외클래스의 인스턴스에 저장된 메시지를 얻을 수 있다. 

## 예외 발생시키기 
키워드 `throw`를 사용해서 프로그래머가 고의로 예외를 발생시킬 수 있다. 

```java
// 먼저, 연산자 new를 이용해서 발생시키려는 예외 클래스의 객체를 만든 다음 
Exception e  = new Exception("고의로 발생시킴");

// throw를 이용해서 예외를 발생시킨다.
throw e;
```
## 메서드에 예외 선언하기 

예외를 처리하는 방법에는 try-catch문 사용 외에, 예외를 메서드에 선언하는 방법이 있다. 
* 메서드에 예외를 선언하려면, **메서드의 선언부에 키워드 throws를 사용해서 메서드 내에서 발생할 수 있는 예외를 적어주기만 하면 된다.**

```java
void method throws Exception 1, Exception2, ... ExceptionN {
  //메서드의 내용
}
```
메서드의 선언부에 예외를 선언함으로써 메서드를 사용하려는 사람이 어떤 예외들이 처리되어야 하는지 쉽게 알 수 있다.

## finally블럭 

* 예외의 발생여부와 관계없이 실행되어야 하는 코드를 포함시킬 목적으로 사용된다. 
* try-catch문의 끝에 선택적으로 덧붙여 사용할 수 있다. (try-catch-finally 순서로 구성)

```java
class FinallyTest {
  public static void main(String args[]) {
    FinallyTest.method1();
  }

  static void method1() {
    try {
      Sytstem.out.println("method1() 호출");
      return;
    } catch(Exception e) {
      e.printStackTrace();
    } finally {
      System.out.prinln("method1()의 finally블럭 실행");
    }
  }
}    
```

try문에서 return문이 실행되는 경우에도 finally블럭이 먼저 실행된 후에, 현재 실행중인 메서드를 종료한다. 
catch블럭의 문장 수행 중에 return문을 만나도 finally블럭의 문장들은 수행된다. 


## 사용자 정의 예외 만들기 
기존에 정의된 예외클래스 외에 필요에 따라  새로운 예외 클래스를 정의할 수 있다. 보통은 `Exception`클래스 또는 `RuntimeException`클래스로부터 상속받아 만들지만, 필요에 따라서 알맞은 예외 클래스를 선택할 수 있다. 

```java
class MyException extends Exception {
  MyException(String msg) {
    super(msg);  //부모인 Exception클래스를 호출한다.
  }
}
```
필요하다면, 멤버 변수나 메서드를 추가할 수 있다. 

## 예외 되던지기 (exception re-throwing)
* 한 메서드에서 여러 개의 예외가 발생할 수 있는 경우, 몇 개는 try-catch문을 통해서 메서드 내에서 자체적으로 처리하고 나머지는 선언부에 지정하여 호출한 메서드에서 처리한다.
* 하나의 예외에 대해서도 예외가 발생한 메서드와 호출한 메서드, 양쪽에서 처리하도록 할 수있다.
* 예외가 발생할 메서드에서는 try-catch문을 사용해서 예외처리를 해줌과 동시에 메서드의 선언부에 발생할 예외를 throws에 지정해줘야 한다.
* 반환값이 있는 return문의 경우, catch블럭에도 return문이 있어야 한다.
  
```java
class Exception2 {
  public static void main(String[] args) {
    try {
      method();
    } catch (Exception e) {
        System.out.println("main메서드에서 예외가 처리되었음.");
    }
  }

  static void method1() throws Exception {
    try {
      throw new Exception();
    } catch(Exception e) {
        System.out.println("method1메서드에서 예외가 처리되었음");
        throw e;  //다시 예외 발생시킴 
    }
  }
}
```

method1()의 catch블럭애서 예외를 처리하고도 throw문을 통해 다시 예외를 발생시킨다. 그리고 이 예외를 main메서드에서 한 번 더 처리한다. 
* catch블럭에서 예외 던지기를 해서 호출한 메서드로 예외를 전달한다면, return문이 없어도 된다.
  
